<?xml version="1.0" encoding="UTF-8"?>
<!-- Generated by org.testng.reporters.JUnitReportReporter -->
<testsuite hostname="DESKTOP-TG48D8J" failures="0" tests="9" name="testCases.ArrayTest" time="20.268" errors="1" timestamp="2022-12-30T18:56:44 EST" skipped="0">
  <testcase classname="testCases.ArrayTest" name="Arrayslogin" time="3.356">
    <error type="junit.framework.AssertionFailedError">
      <![CDATA[junit.framework.AssertionFailedError
at junit.framework.Assert.fail(Assert.java:47)
at junit.framework.Assert.assertTrue(Assert.java:20)
at junit.framework.Assert.assertTrue(Assert.java:27)
at testCases.ArrayTest.Arrayslogin(ArrayTest.java:48)
at java.base/jdk.internal.reflect.DirectMethodHandleAccessor.invoke(DirectMethodHandleAccessor.java:104)
at java.base/java.lang.reflect.Method.invoke(Method.java:577)
at org.testng.internal.MethodInvocationHelper.invokeMethod(MethodInvocationHelper.java:133)
at org.testng.internal.TestInvoker.invokeMethod(TestInvoker.java:598)
at org.testng.internal.TestInvoker.invokeTestMethod(TestInvoker.java:173)
at org.testng.internal.MethodRunner.runInSequence(MethodRunner.java:46)
at org.testng.internal.TestInvoker$MethodInvocationAgent.invoke(TestInvoker.java:824)
at org.testng.internal.TestInvoker.invokeTestMethods(TestInvoker.java:146)
at org.testng.internal.TestMethodWorker.invokeTestMethods(TestMethodWorker.java:146)
at org.testng.internal.TestMethodWorker.run(TestMethodWorker.java:128)
at java.base/java.util.ArrayList.forEach(ArrayList.java:1511)
at org.testng.TestRunner.privateRun(TestRunner.java:794)
at org.testng.TestRunner.run(TestRunner.java:596)
at org.testng.SuiteRunner.runTest(SuiteRunner.java:377)
at org.testng.SuiteRunner.runSequentially(SuiteRunner.java:371)
at org.testng.SuiteRunner.privateRun(SuiteRunner.java:332)
at org.testng.SuiteRunner.run(SuiteRunner.java:276)
at org.testng.SuiteRunnerWorker.runSuite(SuiteRunnerWorker.java:53)
at org.testng.SuiteRunnerWorker.run(SuiteRunnerWorker.java:96)
at org.testng.TestNG.runSuitesSequentially(TestNG.java:1212)
at org.testng.TestNG.runSuitesLocally(TestNG.java:1134)
at org.testng.TestNG.runSuites(TestNG.java:1063)
at org.testng.TestNG.run(TestNG.java:1031)
at org.testng.remote.AbstractRemoteTestNG.run(AbstractRemoteTestNG.java:115)
at org.testng.remote.RemoteTestNG.initAndRun(RemoteTestNG.java:251)
at org.testng.remote.RemoteTestNG.main(RemoteTestNG.java:77)
]]>
    </error>
  </testcase> <!-- Arrayslogin -->
  <system-out/>
  <testcase classname="testCases.ArrayTest" name="ArraysPython" time="2.818"/>
  <system-out/>
  <testcase classname="testCases.ArrayTest" name="ArraysList" time="3.137"/>
  <system-out/>
  <testcase classname="testCases.ArrayTest" name="BasicOperation" time="2.263"/>
  <system-out/>
  <testcase classname="testCases.ArrayTest" name="ApplicationOfArrays" time="1.334"/>
  <system-out/>
  <testcase classname="testCases.ArrayTest" name="PracticeQuestion" time="1.823"/>
  <system-out/>
  <testcase classname="testCases.ArrayTest" name="MaxConsecutive" time="1.018"/>
  <system-out/>
  <testcase classname="testCases.ArrayTest" name="FindNumber" time="0.980"/>
  <system-out/>
  <testcase classname="testCases.ArrayTest" name="ShortedArrays" time="3.539"/>
  <system-out/>
</testsuite> <!-- testCases.ArrayTest -->
